<?xml version="1.0" ?>
<!-- Generated using onshape-to-robot -->
<!-- Onshape https://cad.onshape.com/documents/76b458222900603d1acdcd2d/w/60b37ffbb10251fa10a15486/e/290041a083f12777cf197925 -->
<robot name="arm">
  <!-- Link base_link -->
  <link name="base_link">
    <inertial>
      <origin xyz="2.45641e-17 0.0102883 0.0190249" rpy="0 0 0"/>
      <mass value="0.357273"/>
      <inertia ixx="0.000883446" ixy="5.02926e-22" ixz="-3.76367e-23" iyy="0.00077205" iyz="3.93439e-06" izz="0.00135431"/>
    </inertial>
    <!-- Part ph_pan_head_screw_m2x0_40_x_10__2803432263e518bbd16bccbbef8784ed -->
    <!-- Part base -->
    <visual>
      <origin xyz="-4.07652e-18 9.14136e-05 0.08" rpy="-1.5708 1.50949e-48 -2.46519e-32"/>
      <geometry>
        <mesh filename="package://arm_description/assets/base.stl"/>
      </geometry>
      <material name="base_material">
        <color rgba="0.498039 0.498039 0.498039 1"/>
      </material>
    </visual>
    <collision>
      <origin xyz="-4.07652e-18 9.14136e-05 0.08" rpy="-1.5708 1.50949e-48 -2.46519e-32"/>
      <geometry>
        <mesh filename="package://arm_description/assets/base.stl"/>
      </geometry>
    </collision>
    <!-- Part ph_pan_head_screw_m2x0_40_x_10__2803432263e518bbd16bccbbef8784ed_2 -->
    <!-- Part ph_pan_head_screw_m2x0_40_x_10__2803432263e518bbd16bccbbef8784ed_3 -->
    <!-- Part ph_pan_head_screw_m2x0_40_x_10__2803432263e518bbd16bccbbef8784ed_4 -->
    <!-- Part ph_pan_head_screw_m2x0_40_x_10__2803432263e518bbd16bccbbef8784ed_5 -->
    <!-- Part ph_pan_head_screw_m2x0_40_x_10__2803432263e518bbd16bccbbef8784ed_6 -->
    <!-- Part din_en_iso_4762_m2_5x25_ipt_v2 -->
    <!-- Part din_en_iso_4762_m2_5x25_ipt_v2_2 -->
    <!-- Part din_en_iso_4762_m2_5x25_ipt_v2_3 -->
    <!-- Part din_en_iso_4762_m2_5x25_ipt_v2_4 -->
    <!-- Part servo_base -->
    <visual>
      <origin xyz="1.73201e-17 -0.0119086 0.068" rpy="1.5708 1.5708 0"/>
      <geometry>
        <mesh filename="package://arm_description/assets/servo_base.stl"/>
      </geometry>
      <material name="servo_base_material">
        <color rgba="0.313725 0.313725 0.313725 1"/>
      </material>
    </visual>
    <collision>
      <origin xyz="1.73201e-17 -0.0119086 0.068" rpy="1.5708 1.5708 0"/>
      <geometry>
        <mesh filename="package://arm_description/assets/servo_base.stl"/>
      </geometry>
    </collision>
  </link>
  <!-- Link link_1 -->
  <link name="link_1">
    <inertial>
      <origin xyz="9.31978e-06 -6.78491e-05 -0.0163372" rpy="0 0 0"/>
      <mass value="0.3873"/>
      <inertia ixx="0.000504733" ixy="-1.98908e-07" ixz="-2.92035e-08" iyy="0.000329283" iyz="-1.01741e-07" izz="0.000703592"/>
    </inertial>
    <!-- Part ph_pan_head_screw_m2x0_40_x_10__2803432263e518bbd16bccbbef8784ed_7 -->
    <!-- Part ph_pan_head_screw_m2x0_40_x_10__2803432263e518bbd16bccbbef8784ed_8 -->
    <!-- Part joint_2_connecter -->
    <visual>
      <origin xyz="-1.85585e-18 -4.97131e-05 -0.0045" rpy="1.5708 2.88732e-16 -3.14159"/>
      <geometry>
        <mesh filename="package://arm_description/assets/joint_2_connecter.stl"/>
      </geometry>
      <material name="joint_2_connecter_material">
        <color rgba="0.498039 0.498039 0.498039 1"/>
      </material>
    </visual>
    <collision>
      <origin xyz="-1.85585e-18 -4.97131e-05 -0.0045" rpy="1.5708 2.88732e-16 -3.14159"/>
      <geometry>
        <mesh filename="package://arm_description/assets/joint_2_connecter.stl"/>
      </geometry>
    </collision>
    <!-- Part ph_pan_head_screw_m2x0_40_x_10__2803432263e518bbd16bccbbef8784ed_9 -->
    <!-- Part ph_pan_head_screw_m4x0_70_x_20__cb388d49982372b8fb451041a0f4673b -->
    <!-- Part wheel_gear_v6 -->
    <visual>
      <origin xyz="4.23516e-22 -2.71051e-20 0.0055" rpy="-1.5708 -6.35117e-32 2.76335e-18"/>
      <geometry>
        <mesh filename="package://arm_description/assets/wheel_gear_v6.stl"/>
      </geometry>
      <material name="wheel_gear_v6_material">
        <color rgba="0.960784 0.960784 0.964706 1"/>
      </material>
    </visual>
    <collision>
      <origin xyz="4.23516e-22 -2.71051e-20 0.0055" rpy="-1.5708 -6.35117e-32 2.76335e-18"/>
      <geometry>
        <mesh filename="package://arm_description/assets/wheel_gear_v6.stl"/>
      </geometry>
    </collision>
    <!-- Part base_cover -->
    <visual>
      <origin xyz="-4.22669e-19 5.44812e-18 -0.0045" rpy="1.5708 -2.19343e-16 9.69626e-18"/>
      <geometry>
        <mesh filename="package://arm_description/assets/base_cover.stl"/>
      </geometry>
      <material name="base_cover_material">
        <color rgba="0.498039 0.498039 0.498039 1"/>
      </material>
    </visual>
    <collision>
      <origin xyz="-4.22669e-19 5.44812e-18 -0.0045" rpy="1.5708 -2.19343e-16 9.69626e-18"/>
      <geometry>
        <mesh filename="package://arm_description/assets/base_cover.stl"/>
      </geometry>
    </collision>
    <!-- Part ph_pan_head_screw_m2x0_40_x_10__2803432263e518bbd16bccbbef8784ed_10 -->
    <!-- Part ph_pan_head_screw_m2x0_40_x_10__2803432263e518bbd16bccbbef8784ed_11 -->
    <!-- Part hex_nut_grade_a___b_m4x0_7__3c05376c0eb43b7b72d1a58e9ab268ae -->
    <visual>
      <origin xyz="2.69683e-17 0.037 -0.0261" rpy="-3.14159 6.35117e-32 -3.14159"/>
      <geometry>
        <mesh filename="package://arm_description/assets/hex_nut_grade_a___b_m4x0_7__3c05376c0eb43b7b72d1a58e9ab268ae.stl"/>
      </geometry>
      <material name="hex_nut_grade_a___b_m4x0_7__3c05376c0eb43b7b72d1a58e9ab268ae_material">
        <color rgba="0.603922 0.647059 0.686275 1"/>
      </material>
    </visual>
    <collision>
      <origin xyz="2.69683e-17 0.037 -0.0261" rpy="-3.14159 6.35117e-32 -3.14159"/>
      <geometry>
        <mesh filename="package://arm_description/assets/hex_nut_grade_a___b_m4x0_7__3c05376c0eb43b7b72d1a58e9ab268ae.stl"/>
      </geometry>
    </collision>
    <!-- Part ph_pan_head_screw_m2x0_40_x_10__2803432263e518bbd16bccbbef8784ed_12 -->
    <!-- Part hex_nut_grade_a___b_m4x0_7__3c05376c0eb43b7b72d1a58e9ab268ae_2 -->
    <visual>
      <origin xyz="3.75155e-17 -0.037 -0.0261" rpy="-3.14159 6.35117e-32 -3.14159"/>
      <geometry>
        <mesh filename="package://arm_description/assets/hex_nut_grade_a___b_m4x0_7__3c05376c0eb43b7b72d1a58e9ab268ae.stl"/>
      </geometry>
      <material name="hex_nut_grade_a___b_m4x0_7__3c05376c0eb43b7b72d1a58e9ab268ae_2_material">
        <color rgba="0.603922 0.647059 0.686275 1"/>
      </material>
    </visual>
    <collision>
      <origin xyz="3.75155e-17 -0.037 -0.0261" rpy="-3.14159 6.35117e-32 -3.14159"/>
      <geometry>
        <mesh filename="package://arm_description/assets/hex_nut_grade_a___b_m4x0_7__3c05376c0eb43b7b72d1a58e9ab268ae.stl"/>
      </geometry>
    </collision>
    <!-- Part ph_pan_head_screw_m4x0_70_x_20__cb388d49982372b8fb451041a0f4673b_2 -->
    <!-- Part ph_pan_head_screw_m4x0_70_x_20__cb388d49982372b8fb451041a0f4673b_3 -->
    <!-- Part hex_nut_grade_a___b_m4x0_7__3c05376c0eb43b7b72d1a58e9ab268ae_3 -->
    <visual>
      <origin xyz="1.3918e-17 0.0499751 -0.0261" rpy="-3.14159 6.35117e-32 -3.14159"/>
      <geometry>
        <mesh filename="package://arm_description/assets/hex_nut_grade_a___b_m4x0_7__3c05376c0eb43b7b72d1a58e9ab268ae.stl"/>
      </geometry>
      <material name="hex_nut_grade_a___b_m4x0_7__3c05376c0eb43b7b72d1a58e9ab268ae_3_material">
        <color rgba="0.603922 0.647059 0.686275 1"/>
      </material>
    </visual>
    <collision>
      <origin xyz="1.3918e-17 0.0499751 -0.0261" rpy="-3.14159 6.35117e-32 -3.14159"/>
      <geometry>
        <mesh filename="package://arm_description/assets/hex_nut_grade_a___b_m4x0_7__3c05376c0eb43b7b72d1a58e9ab268ae.stl"/>
      </geometry>
    </collision>
    <!-- Part ph_pan_head_screw_m2x0_40_x_10__2803432263e518bbd16bccbbef8784ed_13 -->
    <!-- Part hex_nut_grade_a___b_m4x0_7__3c05376c0eb43b7b72d1a58e9ab268ae_4 -->
    <visual>
      <origin xyz="4.22864e-17 -0.0500249 -0.0261" rpy="-3.14159 6.35117e-32 -3.14159"/>
      <geometry>
        <mesh filename="package://arm_description/assets/hex_nut_grade_a___b_m4x0_7__3c05376c0eb43b7b72d1a58e9ab268ae.stl"/>
      </geometry>
      <material name="hex_nut_grade_a___b_m4x0_7__3c05376c0eb43b7b72d1a58e9ab268ae_4_material">
        <color rgba="0.603922 0.647059 0.686275 1"/>
      </material>
    </visual>
    <collision>
      <origin xyz="4.22864e-17 -0.0500249 -0.0261" rpy="-3.14159 6.35117e-32 -3.14159"/>
      <geometry>
        <mesh filename="package://arm_description/assets/hex_nut_grade_a___b_m4x0_7__3c05376c0eb43b7b72d1a58e9ab268ae.stl"/>
      </geometry>
    </collision>
    <!-- Part ph_pan_head_screw_m2x0_40_x_10__2803432263e518bbd16bccbbef8784ed_14 -->
    <!-- Part ph_pan_head_screw_m4x0_70_x_20__cb388d49982372b8fb451041a0f4673b_4 -->
    <!-- Part din_en_iso_4762_m2_5x25_ipt_v2_5 -->
    <!-- Part din_en_iso_4762_m2_5x25_ipt_v2_6 -->
    <!-- Part din_en_iso_4762_m2_5x25_ipt_v2_7 -->
    <!-- Part din_en_iso_4762_m2_5x25_ipt_v2_8 -->
    <!-- Part servo_base_2 -->
    <visual>
      <origin xyz="-2.32057e-17 0.0240746 -0.0795" rpy="-3.14159 7.72837e-16 -1.5708"/>
      <geometry>
        <mesh filename="package://arm_description/assets/servo_base__2.stl"/>
      </geometry>
      <material name="servo_base_2_material">
        <color rgba="0.313725 0.313725 0.313725 1"/>
      </material>
    </visual>
    <collision>
      <origin xyz="-2.32057e-17 0.0240746 -0.0795" rpy="-3.14159 7.72837e-16 -1.5708"/>
      <geometry>
        <mesh filename="package://arm_description/assets/servo_base__2.stl"/>
      </geometry>
    </collision>
  </link>
  <!-- Link link_2 -->
  <link name="link_2">
    <inertial>
      <origin xyz="-0.083 1.00053e-18 0.03175" rpy="0 0 0"/>
      <mass value="0.00888911"/>
      <inertia ixx="7.4834e-06" ixy="-1.06144e-20" ixz="-2.85874e-21" iyy="4.53041e-05" iyz="-8.47033e-22" izz="3.95543e-05"/>
    </inertial>
    <!-- Part hex_nut_grade_a___b_m2x0_4__3c416b87f78c3d5d8c04a06ae4c9fdad -->
    <visual>
      <origin xyz="-0.0388 0.0105 0.05175" rpy="-8.92862e-17 -1.5708 0"/>
      <geometry>
        <mesh filename="package://arm_description/assets/hex_nut_grade_a___b_m2x0_4__3c416b87f78c3d5d8c04a06ae4c9fdad.stl"/>
      </geometry>
      <material name="hex_nut_grade_a___b_m2x0_4__3c416b87f78c3d5d8c04a06ae4c9fdad_material">
        <color rgba="0.603922 0.647059 0.686275 1"/>
      </material>
    </visual>
    <collision>
      <origin xyz="-0.0388 0.0105 0.05175" rpy="-8.92862e-17 -1.5708 0"/>
      <geometry>
        <mesh filename="package://arm_description/assets/hex_nut_grade_a___b_m2x0_4__3c416b87f78c3d5d8c04a06ae4c9fdad.stl"/>
      </geometry>
    </collision>
    <!-- Part link__rotation_default_length__cm___10 -->
    <visual>
      <origin xyz="-0.033 3.12936e-18 0.03175" rpy="3.48832e-17 -1.5708 0"/>
      <geometry>
        <mesh filename="package://arm_description/assets/link__rotation_default_length__cm___10.stl"/>
      </geometry>
      <material name="link__rotation_default_length__cm___10_material">
        <color rgba="0.647059 0.647059 0.647059 1"/>
      </material>
    </visual>
    <collision>
      <origin xyz="-0.033 3.12936e-18 0.03175" rpy="3.48832e-17 -1.5708 0"/>
      <geometry>
        <mesh filename="package://arm_description/assets/link__rotation_default_length__cm___10.stl"/>
      </geometry>
    </collision>
    <!-- Part ph_pan_head_screw_m2x0_40_x_10__2803432263e518bbd16bccbbef8784ed_15 -->
    <!-- Part hex_nut_grade_a___b_m2x0_4__3c416b87f78c3d5d8c04a06ae4c9fdad_2 -->
    <visual>
      <origin xyz="-0.1272 0.0105 0.05175" rpy="-3.14159 -1.5708 0"/>
      <geometry>
        <mesh filename="package://arm_description/assets/hex_nut_grade_a___b_m2x0_4__3c416b87f78c3d5d8c04a06ae4c9fdad.stl"/>
      </geometry>
      <material name="hex_nut_grade_a___b_m2x0_4__3c416b87f78c3d5d8c04a06ae4c9fdad_2_material">
        <color rgba="0.603922 0.647059 0.686275 1"/>
      </material>
    </visual>
    <collision>
      <origin xyz="-0.1272 0.0105 0.05175" rpy="-3.14159 -1.5708 0"/>
      <geometry>
        <mesh filename="package://arm_description/assets/hex_nut_grade_a___b_m2x0_4__3c416b87f78c3d5d8c04a06ae4c9fdad.stl"/>
      </geometry>
    </collision>
    <!-- Part ph_pan_head_screw_m2x0_40_x_10__2803432263e518bbd16bccbbef8784ed_16 -->
    <!-- Part ph_pan_head_screw_m2x0_40_x_10__2803432263e518bbd16bccbbef8784ed_17 -->
    <!-- Part hex_nut_grade_a___b_m2x0_4__3c416b87f78c3d5d8c04a06ae4c9fdad_3 -->
    <visual>
      <origin xyz="-0.0388 0.0105 0.01175" rpy="-8.92862e-17 -1.5708 0"/>
      <geometry>
        <mesh filename="package://arm_description/assets/hex_nut_grade_a___b_m2x0_4__3c416b87f78c3d5d8c04a06ae4c9fdad.stl"/>
      </geometry>
      <material name="hex_nut_grade_a___b_m2x0_4__3c416b87f78c3d5d8c04a06ae4c9fdad_3_material">
        <color rgba="0.603922 0.647059 0.686275 1"/>
      </material>
    </visual>
    <collision>
      <origin xyz="-0.0388 0.0105 0.01175" rpy="-8.92862e-17 -1.5708 0"/>
      <geometry>
        <mesh filename="package://arm_description/assets/hex_nut_grade_a___b_m2x0_4__3c416b87f78c3d5d8c04a06ae4c9fdad.stl"/>
      </geometry>
    </collision>
    <!-- Part hex_nut_grade_a___b_m2x0_4__3c416b87f78c3d5d8c04a06ae4c9fdad_4 -->
    <visual>
      <origin xyz="-0.0388 -0.0105 0.01175" rpy="-1.75466e-17 -1.5708 0"/>
      <geometry>
        <mesh filename="package://arm_description/assets/hex_nut_grade_a___b_m2x0_4__3c416b87f78c3d5d8c04a06ae4c9fdad.stl"/>
      </geometry>
      <material name="hex_nut_grade_a___b_m2x0_4__3c416b87f78c3d5d8c04a06ae4c9fdad_4_material">
        <color rgba="0.603922 0.647059 0.686275 1"/>
      </material>
    </visual>
    <collision>
      <origin xyz="-0.0388 -0.0105 0.01175" rpy="-1.75466e-17 -1.5708 0"/>
      <geometry>
        <mesh filename="package://arm_description/assets/hex_nut_grade_a___b_m2x0_4__3c416b87f78c3d5d8c04a06ae4c9fdad.stl"/>
      </geometry>
    </collision>
    <!-- Part ph_pan_head_screw_m2x0_40_x_10__2803432263e518bbd16bccbbef8784ed_18 -->
    <!-- Part hex_nut_grade_a___b_m2x0_4__3c416b87f78c3d5d8c04a06ae4c9fdad_5 -->
    <visual>
      <origin xyz="-0.1272 -0.0105 0.01175" rpy="-3.14159 -1.5708 0"/>
      <geometry>
        <mesh filename="package://arm_description/assets/hex_nut_grade_a___b_m2x0_4__3c416b87f78c3d5d8c04a06ae4c9fdad.stl"/>
      </geometry>
      <material name="hex_nut_grade_a___b_m2x0_4__3c416b87f78c3d5d8c04a06ae4c9fdad_5_material">
        <color rgba="0.603922 0.647059 0.686275 1"/>
      </material>
    </visual>
    <collision>
      <origin xyz="-0.1272 -0.0105 0.01175" rpy="-3.14159 -1.5708 0"/>
      <geometry>
        <mesh filename="package://arm_description/assets/hex_nut_grade_a___b_m2x0_4__3c416b87f78c3d5d8c04a06ae4c9fdad.stl"/>
      </geometry>
    </collision>
    <!-- Part hex_nut_grade_a___b_m2x0_4__3c416b87f78c3d5d8c04a06ae4c9fdad_6 -->
    <visual>
      <origin xyz="-0.1272 0.0105 0.01175" rpy="-3.14159 -1.5708 0"/>
      <geometry>
        <mesh filename="package://arm_description/assets/hex_nut_grade_a___b_m2x0_4__3c416b87f78c3d5d8c04a06ae4c9fdad.stl"/>
      </geometry>
      <material name="hex_nut_grade_a___b_m2x0_4__3c416b87f78c3d5d8c04a06ae4c9fdad_6_material">
        <color rgba="0.603922 0.647059 0.686275 1"/>
      </material>
    </visual>
    <collision>
      <origin xyz="-0.1272 0.0105 0.01175" rpy="-3.14159 -1.5708 0"/>
      <geometry>
        <mesh filename="package://arm_description/assets/hex_nut_grade_a___b_m2x0_4__3c416b87f78c3d5d8c04a06ae4c9fdad.stl"/>
      </geometry>
    </collision>
    <!-- Part ph_pan_head_screw_m2x0_40_x_10__2803432263e518bbd16bccbbef8784ed_19 -->
    <!-- Part ph_pan_head_screw_m2x0_40_x_10__2803432263e518bbd16bccbbef8784ed_20 -->
    <!-- Part ph_pan_head_screw_m2x0_40_x_10__2803432263e518bbd16bccbbef8784ed_21 -->
    <!-- Part ph_pan_head_screw_m2x0_40_x_10__2803432263e518bbd16bccbbef8784ed_22 -->
    <!-- Part hex_nut_grade_a___b_m2x0_4__3c416b87f78c3d5d8c04a06ae4c9fdad_7 -->
    <visual>
      <origin xyz="-0.0388 -0.0105 0.05175" rpy="-8.92862e-17 -1.5708 0"/>
      <geometry>
        <mesh filename="package://arm_description/assets/hex_nut_grade_a___b_m2x0_4__3c416b87f78c3d5d8c04a06ae4c9fdad.stl"/>
      </geometry>
      <material name="hex_nut_grade_a___b_m2x0_4__3c416b87f78c3d5d8c04a06ae4c9fdad_7_material">
        <color rgba="0.603922 0.647059 0.686275 1"/>
      </material>
    </visual>
    <collision>
      <origin xyz="-0.0388 -0.0105 0.05175" rpy="-8.92862e-17 -1.5708 0"/>
      <geometry>
        <mesh filename="package://arm_description/assets/hex_nut_grade_a___b_m2x0_4__3c416b87f78c3d5d8c04a06ae4c9fdad.stl"/>
      </geometry>
    </collision>
    <!-- Part hex_nut_grade_a___b_m2x0_4__3c416b87f78c3d5d8c04a06ae4c9fdad_8 -->
    <visual>
      <origin xyz="-0.1272 -0.0105 0.05175" rpy="-3.14159 -1.5708 0"/>
      <geometry>
        <mesh filename="package://arm_description/assets/hex_nut_grade_a___b_m2x0_4__3c416b87f78c3d5d8c04a06ae4c9fdad.stl"/>
      </geometry>
      <material name="hex_nut_grade_a___b_m2x0_4__3c416b87f78c3d5d8c04a06ae4c9fdad_8_material">
        <color rgba="0.603922 0.647059 0.686275 1"/>
      </material>
    </visual>
    <collision>
      <origin xyz="-0.1272 -0.0105 0.05175" rpy="-3.14159 -1.5708 0"/>
      <geometry>
        <mesh filename="package://arm_description/assets/hex_nut_grade_a___b_m2x0_4__3c416b87f78c3d5d8c04a06ae4c9fdad.stl"/>
      </geometry>
    </collision>
    <!-- Part ph_pan_head_screw_m2x0_40_x_6__e925606c9d0777623cf02b2ae3e987b1 -->
    <!-- Part ph_pan_head_screw_m2x0_40_x_6__e925606c9d0777623cf02b2ae3e987b1_2 -->
    <!-- Part ph_pan_head_screw_m2x0_40_x_6__e925606c9d0777623cf02b2ae3e987b1_3 -->
    <!-- Part ph_pan_head_screw_m2x0_40_x_6__e925606c9d0777623cf02b2ae3e987b1_4 -->
    <!-- Part ph_pan_head_screw_m2x0_40_x_6__e925606c9d0777623cf02b2ae3e987b1_5 -->
    <!-- Part ph_pan_head_screw_m2x0_40_x_6__e925606c9d0777623cf02b2ae3e987b1_6 -->
    <!-- Part ph_pan_head_screw_m2x0_40_x_6__e925606c9d0777623cf02b2ae3e987b1_7 -->
    <!-- Part wheel_gear_v6_2 -->
    <visual>
      <origin xyz="0 -1.54584e-19 0.0055" rpy="-1.5708 1.97215e-31 1.26218e-29"/>
      <geometry>
        <mesh filename="package://arm_description/assets/wheel_gear_v6__2.stl"/>
      </geometry>
      <material name="wheel_gear_v6_2_material">
        <color rgba="0.960784 0.960784 0.964706 1"/>
      </material>
    </visual>
    <collision>
      <origin xyz="0 -1.54584e-19 0.0055" rpy="-1.5708 1.97215e-31 1.26218e-29"/>
      <geometry>
        <mesh filename="package://arm_description/assets/wheel_gear_v6__2.stl"/>
      </geometry>
    </collision>
    <!-- Part ph_pan_head_screw_m2x0_40_x_6__e925606c9d0777623cf02b2ae3e987b1_8 -->
    <!-- Part ph_pan_head_screw_m2x0_40_x_6__e925606c9d0777623cf02b2ae3e987b1_9 -->
    <!-- Part ph_pan_head_screw_m2x0_40_x_6__e925606c9d0777623cf02b2ae3e987b1_10 -->
    <!-- Part large_support -->
    <visual>
      <origin xyz="-0.033 -0.015 -0.0015" rpy="-1.31795e-16 -1.5708 0"/>
      <geometry>
        <mesh filename="package://arm_description/assets/large_support.stl"/>
      </geometry>
      <material name="large_support_material">
        <color rgba="0.960784 0.960784 0.964706 1"/>
      </material>
    </visual>
    <collision>
      <origin xyz="-0.033 -0.015 -0.0015" rpy="-1.31795e-16 -1.5708 0"/>
      <geometry>
        <mesh filename="package://arm_description/assets/large_support.stl"/>
      </geometry>
    </collision>
    <!-- Part ph_pan_head_screw_m2x0_40_x_6__e925606c9d0777623cf02b2ae3e987b1_11 -->
    <!-- Part ph_pan_head_screw_m2x0_40_x_6__e925606c9d0777623cf02b2ae3e987b1_12 -->
    <!-- Part ph_pan_head_screw_m2x0_40_x_6__e925606c9d0777623cf02b2ae3e987b1_13 -->
    <!-- Part ph_pan_head_screw_m2x0_40_x_6__e925606c9d0777623cf02b2ae3e987b1_14 -->
    <!-- Part ph_pan_head_screw_m2x0_40_x_6__e925606c9d0777623cf02b2ae3e987b1_15 -->
    <!-- Part ph_pan_head_screw_m2x0_40_x_6__e925606c9d0777623cf02b2ae3e987b1_16 -->
    <!-- Part ph_pan_head_screw_m2x0_40_x_6__e925606c9d0777623cf02b2ae3e987b1_17 -->
    <!-- Part wheel_gear_v6_3 -->
    <visual>
      <origin xyz="-0.166 -1.87237e-18 0.0055" rpy="-1.5708 -6.97562e-17 -3.14159"/>
      <geometry>
        <mesh filename="package://arm_description/assets/wheel_gear_v6__2.stl"/>
      </geometry>
      <material name="wheel_gear_v6_3_material">
        <color rgba="0.960784 0.960784 0.964706 1"/>
      </material>
    </visual>
    <collision>
      <origin xyz="-0.166 -1.87237e-18 0.0055" rpy="-1.5708 -6.97562e-17 -3.14159"/>
      <geometry>
        <mesh filename="package://arm_description/assets/wheel_gear_v6__2.stl"/>
      </geometry>
    </collision>
    <!-- Part ph_pan_head_screw_m2x0_40_x_6__e925606c9d0777623cf02b2ae3e987b1_18 -->
    <!-- Part ph_pan_head_screw_m2x0_40_x_6__e925606c9d0777623cf02b2ae3e987b1_19 -->
    <!-- Part ph_pan_head_screw_m2x0_40_x_6__e925606c9d0777623cf02b2ae3e987b1_20 -->
    <!-- Part large_support_2 -->
    <visual>
      <origin xyz="-0.133 0.015 -0.0015" rpy="-3.14159 -1.5708 0"/>
      <geometry>
        <mesh filename="package://arm_description/assets/large_support.stl"/>
      </geometry>
      <material name="large_support_2_material">
        <color rgba="0.960784 0.960784 0.964706 1"/>
      </material>
    </visual>
    <collision>
      <origin xyz="-0.133 0.015 -0.0015" rpy="-3.14159 -1.5708 0"/>
      <geometry>
        <mesh filename="package://arm_description/assets/large_support.stl"/>
      </geometry>
    </collision>
    <!-- Part 6mm_bearing_v2 -->
    <visual>
      <origin xyz="8.32667e-17 8.11775e-17 0.0595" rpy="-1.5708 1.5708 0"/>
      <geometry>
        <mesh filename="package://arm_description/assets/6mm_bearing_v2.stl"/>
      </geometry>
      <material name="6mm_bearing_v2_material">
        <color rgba="0.627451 0.627451 0.627451 1"/>
      </material>
    </visual>
    <collision>
      <origin xyz="8.32667e-17 8.11775e-17 0.0595" rpy="-1.5708 1.5708 0"/>
      <geometry>
        <mesh filename="package://arm_description/assets/6mm_bearing_v2.stl"/>
      </geometry>
    </collision>
    <!-- Part wheel_v5 -->
    <visual>
      <origin xyz="1.11022e-16 -1.47384e-19 0.058" rpy="1.5708 -4.64932e-16 -3.14159"/>
      <geometry>
        <mesh filename="package://arm_description/assets/wheel_v5.stl"/>
      </geometry>
      <material name="wheel_v5_material">
        <color rgba="0.960784 0.960784 0.964706 1"/>
      </material>
    </visual>
    <collision>
      <origin xyz="1.11022e-16 -1.47384e-19 0.058" rpy="1.5708 -4.64932e-16 -3.14159"/>
      <geometry>
        <mesh filename="package://arm_description/assets/wheel_v5.stl"/>
      </geometry>
    </collision>
    <!-- Part 6mm_bearing_v2_2 -->
    <visual>
      <origin xyz="-0.166 -8.94535e-17 0.0595" rpy="1.5708 1.5708 0"/>
      <geometry>
        <mesh filename="package://arm_description/assets/6mm_bearing_v2.stl"/>
      </geometry>
      <material name="6mm_bearing_v2_2_material">
        <color rgba="0.627451 0.627451 0.627451 1"/>
      </material>
    </visual>
    <collision>
      <origin xyz="-0.166 -8.94535e-17 0.0595" rpy="1.5708 1.5708 0"/>
      <geometry>
        <mesh filename="package://arm_description/assets/6mm_bearing_v2.stl"/>
      </geometry>
    </collision>
    <!-- Part wheel_v5_2 -->
    <visual>
      <origin xyz="-0.166 -2.23024e-18 0.058" rpy="1.5708 7.20799e-17 1.48979e-16"/>
      <geometry>
        <mesh filename="package://arm_description/assets/wheel_v5.stl"/>
      </geometry>
      <material name="wheel_v5_2_material">
        <color rgba="0.960784 0.960784 0.964706 1"/>
      </material>
    </visual>
    <collision>
      <origin xyz="-0.166 -2.23024e-18 0.058" rpy="1.5708 7.20799e-17 1.48979e-16"/>
      <geometry>
        <mesh filename="package://arm_description/assets/wheel_v5.stl"/>
      </geometry>
    </collision>
  </link>
  <!-- Link link_3 -->
  <link name="link_3">
    <inertial>
      <origin xyz="-7.28157e-06 0.112 -0.029598" rpy="0 0 0"/>
      <mass value="0.00639747"/>
      <inertia ixx="2.30806e-05" ixy="2.05867e-09" ixz="-1.52748e-09" iyy="3.77589e-06" iyz="2.06999e-09" izz="2.07504e-05"/>
    </inertial>
    <!-- Part link__rotation_default_length__cm___10_2 -->
    <visual>
      <origin xyz="-1.90449e-15 0.162 -0.0315" rpy="1.5708 -1.5708 0"/>
      <geometry>
        <mesh filename="package://arm_description/assets/link__rotation_default_length__cm___10.stl"/>
      </geometry>
      <material name="link__rotation_default_length__cm___10_2_material">
        <color rgba="0.647059 0.647059 0.647059 1"/>
      </material>
    </visual>
    <collision>
      <origin xyz="-1.90449e-15 0.162 -0.0315" rpy="1.5708 -1.5708 0"/>
      <geometry>
        <mesh filename="package://arm_description/assets/link__rotation_default_length__cm___10.stl"/>
      </geometry>
    </collision>
    <!-- Part ph_pan_head_screw_m2x0_40_x_10__2803432263e518bbd16bccbbef8784ed_23 -->
    <!-- Part hex_nut_grade_a___b_m2x0_4__3c416b87f78c3d5d8c04a06ae4c9fdad_9 -->
    <visual>
      <origin xyz="-0.0105 0.1562 -0.0115" rpy="1.5708 -1.5708 0"/>
      <geometry>
        <mesh filename="package://arm_description/assets/hex_nut_grade_a___b_m2x0_4__3c416b87f78c3d5d8c04a06ae4c9fdad.stl"/>
      </geometry>
      <material name="hex_nut_grade_a___b_m2x0_4__3c416b87f78c3d5d8c04a06ae4c9fdad_9_material">
        <color rgba="0.603922 0.647059 0.686275 1"/>
      </material>
    </visual>
    <collision>
      <origin xyz="-0.0105 0.1562 -0.0115" rpy="1.5708 -1.5708 0"/>
      <geometry>
        <mesh filename="package://arm_description/assets/hex_nut_grade_a___b_m2x0_4__3c416b87f78c3d5d8c04a06ae4c9fdad.stl"/>
      </geometry>
    </collision>
    <!-- Part ph_pan_head_screw_m2x0_40_x_6__e925606c9d0777623cf02b2ae3e987b1_21 -->
    <!-- Part ph_pan_head_screw_m2x0_40_x_6__e925606c9d0777623cf02b2ae3e987b1_22 -->
    <!-- Part small_support -->
    <visual>
      <origin xyz="0.015 0.162 -0.0575" rpy="1.5708 -1.5708 0"/>
      <geometry>
        <mesh filename="package://arm_description/assets/small_support.stl"/>
      </geometry>
      <material name="small_support_material">
        <color rgba="0.960784 0.960784 0.964706 1"/>
      </material>
    </visual>
    <collision>
      <origin xyz="0.015 0.162 -0.0575" rpy="1.5708 -1.5708 0"/>
      <geometry>
        <mesh filename="package://arm_description/assets/small_support.stl"/>
      </geometry>
    </collision>
    <!-- Part ph_pan_head_screw_m2x0_40_x_6__e925606c9d0777623cf02b2ae3e987b1_23 -->
    <!-- Part hex_nut_grade_a___b_m2x0_4__3c416b87f78c3d5d8c04a06ae4c9fdad_10 -->
    <visual>
      <origin xyz="0.0105 0.0678 -0.0115" rpy="-1.5708 -1.5708 0"/>
      <geometry>
        <mesh filename="package://arm_description/assets/hex_nut_grade_a___b_m2x0_4__3c416b87f78c3d5d8c04a06ae4c9fdad.stl"/>
      </geometry>
      <material name="hex_nut_grade_a___b_m2x0_4__3c416b87f78c3d5d8c04a06ae4c9fdad_10_material">
        <color rgba="0.603922 0.647059 0.686275 1"/>
      </material>
    </visual>
    <collision>
      <origin xyz="0.0105 0.0678 -0.0115" rpy="-1.5708 -1.5708 0"/>
      <geometry>
        <mesh filename="package://arm_description/assets/hex_nut_grade_a___b_m2x0_4__3c416b87f78c3d5d8c04a06ae4c9fdad.stl"/>
      </geometry>
    </collision>
    <!-- Part hex_nut_grade_a___b_m2x0_4__3c416b87f78c3d5d8c04a06ae4c9fdad_11 -->
    <visual>
      <origin xyz="0.0105 0.1562 -0.0115" rpy="1.5708 -1.5708 0"/>
      <geometry>
        <mesh filename="package://arm_description/assets/hex_nut_grade_a___b_m2x0_4__3c416b87f78c3d5d8c04a06ae4c9fdad.stl"/>
      </geometry>
      <material name="hex_nut_grade_a___b_m2x0_4__3c416b87f78c3d5d8c04a06ae4c9fdad_11_material">
        <color rgba="0.603922 0.647059 0.686275 1"/>
      </material>
    </visual>
    <collision>
      <origin xyz="0.0105 0.1562 -0.0115" rpy="1.5708 -1.5708 0"/>
      <geometry>
        <mesh filename="package://arm_description/assets/hex_nut_grade_a___b_m2x0_4__3c416b87f78c3d5d8c04a06ae4c9fdad.stl"/>
      </geometry>
    </collision>
    <!-- Part ph_pan_head_screw_m2x0_40_x_10__2803432263e518bbd16bccbbef8784ed_24 -->
    <!-- Part hex_nut_grade_a___b_m2x0_4__3c416b87f78c3d5d8c04a06ae4c9fdad_12 -->
    <visual>
      <origin xyz="-0.0105 0.0678 -0.0515" rpy="-1.5708 -1.5708 0"/>
      <geometry>
        <mesh filename="package://arm_description/assets/hex_nut_grade_a___b_m2x0_4__3c416b87f78c3d5d8c04a06ae4c9fdad.stl"/>
      </geometry>
      <material name="hex_nut_grade_a___b_m2x0_4__3c416b87f78c3d5d8c04a06ae4c9fdad_12_material">
        <color rgba="0.603922 0.647059 0.686275 1"/>
      </material>
    </visual>
    <collision>
      <origin xyz="-0.0105 0.0678 -0.0515" rpy="-1.5708 -1.5708 0"/>
      <geometry>
        <mesh filename="package://arm_description/assets/hex_nut_grade_a___b_m2x0_4__3c416b87f78c3d5d8c04a06ae4c9fdad.stl"/>
      </geometry>
    </collision>
    <!-- Part ph_pan_head_screw_m2x0_40_x_10__2803432263e518bbd16bccbbef8784ed_25 -->
    <!-- Part ph_pan_head_screw_m2x0_40_x_6__e925606c9d0777623cf02b2ae3e987b1_24 -->
    <!-- Part ph_pan_head_screw_m2x0_40_x_6__e925606c9d0777623cf02b2ae3e987b1_25 -->
    <!-- Part ph_pan_head_screw_m2x0_40_x_10__2803432263e518bbd16bccbbef8784ed_26 -->
    <!-- Part ph_pan_head_screw_m2x0_40_x_10__2803432263e518bbd16bccbbef8784ed_27 -->
    <!-- Part small_support_2 -->
    <visual>
      <origin xyz="-0.015 0.062 -0.0575" rpy="-1.5708 -1.5708 0"/>
      <geometry>
        <mesh filename="package://arm_description/assets/small_support.stl"/>
      </geometry>
      <material name="small_support_2_material">
        <color rgba="0.960784 0.960784 0.964706 1"/>
      </material>
    </visual>
    <collision>
      <origin xyz="-0.015 0.062 -0.0575" rpy="-1.5708 -1.5708 0"/>
      <geometry>
        <mesh filename="package://arm_description/assets/small_support.stl"/>
      </geometry>
    </collision>
    <!-- Part ph_pan_head_screw_m2x0_40_x_10__2803432263e518bbd16bccbbef8784ed_28 -->
    <!-- Part ph_pan_head_screw_m2x0_40_x_6__e925606c9d0777623cf02b2ae3e987b1_26 -->
    <!-- Part hex_nut_grade_a___b_m2x0_4__3c416b87f78c3d5d8c04a06ae4c9fdad_13 -->
    <visual>
      <origin xyz="-0.0108285 0.1562 -0.0518303" rpy="1.5708 -1.5708 0"/>
      <geometry>
        <mesh filename="package://arm_description/assets/hex_nut_grade_a___b_m2x0_4__3c416b87f78c3d5d8c04a06ae4c9fdad.stl"/>
      </geometry>
      <material name="hex_nut_grade_a___b_m2x0_4__3c416b87f78c3d5d8c04a06ae4c9fdad_13_material">
        <color rgba="0.603922 0.647059 0.686275 1"/>
      </material>
    </visual>
    <collision>
      <origin xyz="-0.0108285 0.1562 -0.0518303" rpy="1.5708 -1.5708 0"/>
      <geometry>
        <mesh filename="package://arm_description/assets/hex_nut_grade_a___b_m2x0_4__3c416b87f78c3d5d8c04a06ae4c9fdad.stl"/>
      </geometry>
    </collision>
    <!-- Part ph_pan_head_screw_m2x0_40_x_6__e925606c9d0777623cf02b2ae3e987b1_27 -->
    <!-- Part ph_pan_head_screw_m2x0_40_x_6__e925606c9d0777623cf02b2ae3e987b1_28 -->
    <!-- Part hex_nut_grade_a___b_m2x0_4__3c416b87f78c3d5d8c04a06ae4c9fdad_14 -->
    <visual>
      <origin xyz="-0.0105 0.0678 -0.0115" rpy="-1.5708 -1.5708 0"/>
      <geometry>
        <mesh filename="package://arm_description/assets/hex_nut_grade_a___b_m2x0_4__3c416b87f78c3d5d8c04a06ae4c9fdad.stl"/>
      </geometry>
      <material name="hex_nut_grade_a___b_m2x0_4__3c416b87f78c3d5d8c04a06ae4c9fdad_14_material">
        <color rgba="0.603922 0.647059 0.686275 1"/>
      </material>
    </visual>
    <collision>
      <origin xyz="-0.0105 0.0678 -0.0115" rpy="-1.5708 -1.5708 0"/>
      <geometry>
        <mesh filename="package://arm_description/assets/hex_nut_grade_a___b_m2x0_4__3c416b87f78c3d5d8c04a06ae4c9fdad.stl"/>
      </geometry>
    </collision>
    <!-- Part ph_pan_head_screw_m2x0_40_x_10__2803432263e518bbd16bccbbef8784ed_29 -->
    <!-- Part ph_pan_head_screw_m2x0_40_x_6__e925606c9d0777623cf02b2ae3e987b1_29 -->
    <!-- Part hex_nut_grade_a___b_m2x0_4__3c416b87f78c3d5d8c04a06ae4c9fdad_15 -->
    <visual>
      <origin xyz="0.0105 0.0678 -0.0515" rpy="-1.5708 -1.5708 0"/>
      <geometry>
        <mesh filename="package://arm_description/assets/hex_nut_grade_a___b_m2x0_4__3c416b87f78c3d5d8c04a06ae4c9fdad.stl"/>
      </geometry>
      <material name="hex_nut_grade_a___b_m2x0_4__3c416b87f78c3d5d8c04a06ae4c9fdad_15_material">
        <color rgba="0.603922 0.647059 0.686275 1"/>
      </material>
    </visual>
    <collision>
      <origin xyz="0.0105 0.0678 -0.0515" rpy="-1.5708 -1.5708 0"/>
      <geometry>
        <mesh filename="package://arm_description/assets/hex_nut_grade_a___b_m2x0_4__3c416b87f78c3d5d8c04a06ae4c9fdad.stl"/>
      </geometry>
    </collision>
    <!-- Part ph_pan_head_screw_m2x0_40_x_10__2803432263e518bbd16bccbbef8784ed_30 -->
    <!-- Part ph_pan_head_screw_m2x0_40_x_6__e925606c9d0777623cf02b2ae3e987b1_30 -->
    <!-- Part hex_nut_grade_a___b_m2x0_4__3c416b87f78c3d5d8c04a06ae4c9fdad_16 -->
    <visual>
      <origin xyz="0.0105 0.1562 -0.0515" rpy="1.5708 -1.5708 0"/>
      <geometry>
        <mesh filename="package://arm_description/assets/hex_nut_grade_a___b_m2x0_4__3c416b87f78c3d5d8c04a06ae4c9fdad.stl"/>
      </geometry>
      <material name="hex_nut_grade_a___b_m2x0_4__3c416b87f78c3d5d8c04a06ae4c9fdad_16_material">
        <color rgba="0.603922 0.647059 0.686275 1"/>
      </material>
    </visual>
    <collision>
      <origin xyz="0.0105 0.1562 -0.0515" rpy="1.5708 -1.5708 0"/>
      <geometry>
        <mesh filename="package://arm_description/assets/hex_nut_grade_a___b_m2x0_4__3c416b87f78c3d5d8c04a06ae4c9fdad.stl"/>
      </geometry>
    </collision>
    <!-- Part din_en_iso_4762_m2_5x25_ipt_v2_9 -->
    <!-- Part din_en_iso_4762_m2_5x25_ipt_v2_10 -->
    <!-- Part din_en_iso_4762_m2_5x25_ipt_v2_11 -->
    <!-- Part din_en_iso_4762_m2_5x25_ipt_v2_12 -->
    <!-- Part servo_base_3 -->
    <visual>
      <origin xyz="-1.77854e-15 0.236 -0.0075" rpy="-1.5708 1.5708 0"/>
      <geometry>
        <mesh filename="package://arm_description/assets/servo_base__2.stl"/>
      </geometry>
      <material name="servo_base_3_material">
        <color rgba="0.313725 0.313725 0.313725 1"/>
      </material>
    </visual>
    <collision>
      <origin xyz="-1.77854e-15 0.236 -0.0075" rpy="-1.5708 1.5708 0"/>
      <geometry>
        <mesh filename="package://arm_description/assets/servo_base__2.stl"/>
      </geometry>
    </collision>
    <!-- Part din_en_iso_4762_m2_5x25_ipt_v2_13 -->
    <!-- Part din_en_iso_4762_m2_5x25_ipt_v2_14 -->
    <!-- Part din_en_iso_4762_m2_5x25_ipt_v2_15 -->
    <!-- Part din_en_iso_4762_m2_5x25_ipt_v2_16 -->
    <!-- Part servo_base_4 -->
    <visual>
      <origin xyz="4.19281e-20 -0.012 -0.0075" rpy="1.5708 1.5708 0"/>
      <geometry>
        <mesh filename="package://arm_description/assets/servo_base__2.stl"/>
      </geometry>
      <material name="servo_base_4_material">
        <color rgba="0.313725 0.313725 0.313725 1"/>
      </material>
    </visual>
    <collision>
      <origin xyz="4.19281e-20 -0.012 -0.0075" rpy="1.5708 1.5708 0"/>
      <geometry>
        <mesh filename="package://arm_description/assets/servo_base__2.stl"/>
      </geometry>
    </collision>
  </link>
  <!-- Link link_4 -->
  <link name="link_4">
    <inertial>
      <origin xyz="-0.0243394 0.00115207 0.03175" rpy="0 0 0"/>
      <mass value="0.00530132"/>
      <inertia ixx="3.8628e-06" ixy="2.72765e-07" ixz="-4.35686e-09" iyy="4.70304e-06" iyz="-4.97632e-21" izz="2.99733e-06"/>
    </inertial>
    <!-- Part ph_pan_head_screw_m2x0_40_x_6__e925606c9d0777623cf02b2ae3e987b1_31 -->
    <!-- Part hex_nut_grade_a___b_m2x0_4__3c416b87f78c3d5d8c04a06ae4c9fdad_17 -->
    <visual>
      <origin xyz="-0.0358 0.0085 0.04025" rpy="-1.5708 -4.99542e-15 1.5708"/>
      <geometry>
        <mesh filename="package://arm_description/assets/hex_nut_grade_a___b_m2x0_4__3c416b87f78c3d5d8c04a06ae4c9fdad.stl"/>
      </geometry>
      <material name="hex_nut_grade_a___b_m2x0_4__3c416b87f78c3d5d8c04a06ae4c9fdad_17_material">
        <color rgba="0.603922 0.647059 0.686275 1"/>
      </material>
    </visual>
    <collision>
      <origin xyz="-0.0358 0.0085 0.04025" rpy="-1.5708 -4.99542e-15 1.5708"/>
      <geometry>
        <mesh filename="package://arm_description/assets/hex_nut_grade_a___b_m2x0_4__3c416b87f78c3d5d8c04a06ae4c9fdad.stl"/>
      </geometry>
    </collision>
    <!-- Part ph_pan_head_screw_m2x0_40_x_6__e925606c9d0777623cf02b2ae3e987b1_32 -->
    <!-- Part ph_pan_head_screw_m2x0_40_x_6__e925606c9d0777623cf02b2ae3e987b1_33 -->
    <!-- Part small_support_3 -->
    <visual>
      <origin xyz="-0.033 -0.026 0.01675" rpy="1.5708 -5.00393e-15 1.5708"/>
      <geometry>
        <mesh filename="package://arm_description/assets/small_support.stl"/>
      </geometry>
      <material name="small_support_3_material">
        <color rgba="0.960784 0.960784 0.964706 1"/>
      </material>
    </visual>
    <collision>
      <origin xyz="-0.033 -0.026 0.01675" rpy="1.5708 -5.00393e-15 1.5708"/>
      <geometry>
        <mesh filename="package://arm_description/assets/small_support.stl"/>
      </geometry>
    </collision>
    <!-- Part ph_pan_head_screw_m2x0_40_x_6__e925606c9d0777623cf02b2ae3e987b1_34 -->
    <!-- Part hex_nut_grade_a___b_m2x0_4__3c416b87f78c3d5d8c04a06ae4c9fdad_18 -->
    <visual>
      <origin xyz="-0.0358 0.0085 0.02325" rpy="-1.5708 -4.99542e-15 1.5708"/>
      <geometry>
        <mesh filename="package://arm_description/assets/hex_nut_grade_a___b_m2x0_4__3c416b87f78c3d5d8c04a06ae4c9fdad.stl"/>
      </geometry>
      <material name="hex_nut_grade_a___b_m2x0_4__3c416b87f78c3d5d8c04a06ae4c9fdad_18_material">
        <color rgba="0.603922 0.647059 0.686275 1"/>
      </material>
    </visual>
    <collision>
      <origin xyz="-0.0358 0.0085 0.02325" rpy="-1.5708 -4.99542e-15 1.5708"/>
      <geometry>
        <mesh filename="package://arm_description/assets/hex_nut_grade_a___b_m2x0_4__3c416b87f78c3d5d8c04a06ae4c9fdad.stl"/>
      </geometry>
    </collision>
    <!-- Part hex_nut_grade_a___b_m2x0_4__3c416b87f78c3d5d8c04a06ae4c9fdad_19 -->
    <visual>
      <origin xyz="-0.0358 -0.0085 0.04025" rpy="-1.5708 -4.99542e-15 1.5708"/>
      <geometry>
        <mesh filename="package://arm_description/assets/hex_nut_grade_a___b_m2x0_4__3c416b87f78c3d5d8c04a06ae4c9fdad.stl"/>
      </geometry>
      <material name="hex_nut_grade_a___b_m2x0_4__3c416b87f78c3d5d8c04a06ae4c9fdad_19_material">
        <color rgba="0.603922 0.647059 0.686275 1"/>
      </material>
    </visual>
    <collision>
      <origin xyz="-0.0358 -0.0085 0.04025" rpy="-1.5708 -4.99542e-15 1.5708"/>
      <geometry>
        <mesh filename="package://arm_description/assets/hex_nut_grade_a___b_m2x0_4__3c416b87f78c3d5d8c04a06ae4c9fdad.stl"/>
      </geometry>
    </collision>
    <!-- Part ph_pan_head_screw_m2x0_40_x_6__e925606c9d0777623cf02b2ae3e987b1_35 -->
    <!-- Part ph_pan_head_screw_m2x0_40_x_6__e925606c9d0777623cf02b2ae3e987b1_36 -->
    <!-- Part ph_pan_head_screw_m2x0_40_x_6__e925606c9d0777623cf02b2ae3e987b1_37 -->
    <!-- Part ph_pan_head_screw_m2x0_40_x_6__e925606c9d0777623cf02b2ae3e987b1_38 -->
    <!-- Part hex_nut_grade_a___b_m2x0_4__3c416b87f78c3d5d8c04a06ae4c9fdad_20 -->
    <visual>
      <origin xyz="-0.0358 -0.0085 0.02325" rpy="-1.5708 -4.99542e-15 1.5708"/>
      <geometry>
        <mesh filename="package://arm_description/assets/hex_nut_grade_a___b_m2x0_4__3c416b87f78c3d5d8c04a06ae4c9fdad.stl"/>
      </geometry>
      <material name="hex_nut_grade_a___b_m2x0_4__3c416b87f78c3d5d8c04a06ae4c9fdad_20_material">
        <color rgba="0.603922 0.647059 0.686275 1"/>
      </material>
    </visual>
    <collision>
      <origin xyz="-0.0358 -0.0085 0.02325" rpy="-1.5708 -4.99542e-15 1.5708"/>
      <geometry>
        <mesh filename="package://arm_description/assets/hex_nut_grade_a___b_m2x0_4__3c416b87f78c3d5d8c04a06ae4c9fdad.stl"/>
      </geometry>
    </collision>
    <!-- Part ph_pan_head_screw_m2x0_40_x_6__e925606c9d0777623cf02b2ae3e987b1_39 -->
    <!-- Part din_en_iso_4762_m2_5x25_ipt_v2_17 -->
    <!-- Part din_en_iso_4762_m2_5x25_ipt_v2_18 -->
    <!-- Part din_en_iso_4762_m2_5x25_ipt_v2_19 -->
    <!-- Part din_en_iso_4762_m2_5x25_ipt_v2_20 -->
    <!-- Part servo_base_5 -->
    <visual>
      <origin xyz="-0.107 0.024 0.03175" rpy="1.5708 4.83071e-15 -1.5708"/>
      <geometry>
        <mesh filename="package://arm_description/assets/servo_base__2.stl"/>
      </geometry>
      <material name="servo_base_5_material">
        <color rgba="0.313725 0.313725 0.313725 1"/>
      </material>
    </visual>
    <collision>
      <origin xyz="-0.107 0.024 0.03175" rpy="1.5708 4.83071e-15 -1.5708"/>
      <geometry>
        <mesh filename="package://arm_description/assets/servo_base__2.stl"/>
      </geometry>
    </collision>
    <!-- Part ph_pan_head_screw_m2x0_40_x_6__e925606c9d0777623cf02b2ae3e987b1_40 -->
    <!-- Part ph_pan_head_screw_m2x0_40_x_6__e925606c9d0777623cf02b2ae3e987b1_41 -->
    <!-- Part ph_pan_head_screw_m2x0_40_x_6__e925606c9d0777623cf02b2ae3e987b1_42 -->
    <!-- Part ph_pan_head_screw_m2x0_40_x_6__e925606c9d0777623cf02b2ae3e987b1_43 -->
    <!-- Part ph_pan_head_screw_m2x0_40_x_6__e925606c9d0777623cf02b2ae3e987b1_44 -->
    <!-- Part ph_pan_head_screw_m2x0_40_x_6__e925606c9d0777623cf02b2ae3e987b1_45 -->
    <!-- Part ph_pan_head_screw_m2x0_40_x_6__e925606c9d0777623cf02b2ae3e987b1_46 -->
    <!-- Part wheel_gear_v6_4 -->
    <visual>
      <origin xyz="0 -1.68983e-19 0.0055" rpy="-1.5708 1.35066e-31 6.94706e-30"/>
      <geometry>
        <mesh filename="package://arm_description/assets/wheel_gear_v6__2.stl"/>
      </geometry>
      <material name="wheel_gear_v6_4_material">
        <color rgba="0.960784 0.960784 0.964706 1"/>
      </material>
    </visual>
    <collision>
      <origin xyz="0 -1.68983e-19 0.0055" rpy="-1.5708 1.35066e-31 6.94706e-30"/>
      <geometry>
        <mesh filename="package://arm_description/assets/wheel_gear_v6__2.stl"/>
      </geometry>
    </collision>
    <!-- Part ph_pan_head_screw_m2x0_40_x_6__e925606c9d0777623cf02b2ae3e987b1_47 -->
    <!-- Part ph_pan_head_screw_m2x0_40_x_6__e925606c9d0777623cf02b2ae3e987b1_48 -->
    <!-- Part ph_pan_head_screw_m2x0_40_x_6__e925606c9d0777623cf02b2ae3e987b1_49 -->
    <!-- Part large_support_3 -->
    <visual>
      <origin xyz="-0.033 -0.015 -0.0015" rpy="-3.65856e-17 -1.5708 0"/>
      <geometry>
        <mesh filename="package://arm_description/assets/large_support.stl"/>
      </geometry>
      <material name="large_support_3_material">
        <color rgba="0.960784 0.960784 0.964706 1"/>
      </material>
    </visual>
    <collision>
      <origin xyz="-0.033 -0.015 -0.0015" rpy="-3.65856e-17 -1.5708 0"/>
      <geometry>
        <mesh filename="package://arm_description/assets/large_support.stl"/>
      </geometry>
    </collision>
    <!-- Part 6mm_bearing_v2_3 -->
    <visual>
      <origin xyz="1.11022e-16 -2.90998e-17 0.0595" rpy="-1.5708 1.5708 0"/>
      <geometry>
        <mesh filename="package://arm_description/assets/6mm_bearing_v2.stl"/>
      </geometry>
      <material name="6mm_bearing_v2_3_material">
        <color rgba="0.627451 0.627451 0.627451 1"/>
      </material>
    </visual>
    <collision>
      <origin xyz="1.11022e-16 -2.90998e-17 0.0595" rpy="-1.5708 1.5708 0"/>
      <geometry>
        <mesh filename="package://arm_description/assets/6mm_bearing_v2.stl"/>
      </geometry>
    </collision>
    <!-- Part wheel_v5_3 -->
    <visual>
      <origin xyz="1.11022e-16 7.37342e-19 0.058" rpy="1.5708 8.74137e-16 3.14159"/>
      <geometry>
        <mesh filename="package://arm_description/assets/wheel_v5.stl"/>
      </geometry>
      <material name="wheel_v5_3_material">
        <color rgba="0.960784 0.960784 0.964706 1"/>
      </material>
    </visual>
    <collision>
      <origin xyz="1.11022e-16 7.37342e-19 0.058" rpy="1.5708 8.74137e-16 3.14159"/>
      <geometry>
        <mesh filename="package://arm_description/assets/wheel_v5.stl"/>
      </geometry>
    </collision>
  </link>
  <!-- Link link_5 -->
  <link name="link_5">
    <inertial>
      <origin xyz="-0.0243394 0.00115207 0.03175" rpy="0 0 0"/>
      <mass value="0.00530132"/>
      <inertia ixx="3.8628e-06" ixy="2.72765e-07" ixz="-4.35686e-09" iyy="4.70304e-06" iyz="-2.64698e-22" izz="2.99733e-06"/>
    </inertial>
    <!-- Part ph_pan_head_screw_m2x0_40_x_6__e925606c9d0777623cf02b2ae3e987b1_50 -->
    <!-- Part hex_nut_grade_a___b_m2x0_4__3c416b87f78c3d5d8c04a06ae4c9fdad_21 -->
    <visual>
      <origin xyz="-0.0358 0.0085 0.02325" rpy="-1.5708 -3.28491e-16 1.5708"/>
      <geometry>
        <mesh filename="package://arm_description/assets/hex_nut_grade_a___b_m2x0_4__3c416b87f78c3d5d8c04a06ae4c9fdad.stl"/>
      </geometry>
      <material name="hex_nut_grade_a___b_m2x0_4__3c416b87f78c3d5d8c04a06ae4c9fdad_21_material">
        <color rgba="0.603922 0.647059 0.686275 1"/>
      </material>
    </visual>
    <collision>
      <origin xyz="-0.0358 0.0085 0.02325" rpy="-1.5708 -3.28491e-16 1.5708"/>
      <geometry>
        <mesh filename="package://arm_description/assets/hex_nut_grade_a___b_m2x0_4__3c416b87f78c3d5d8c04a06ae4c9fdad.stl"/>
      </geometry>
    </collision>
    <!-- Part ph_pan_head_screw_m2x0_40_x_6__e925606c9d0777623cf02b2ae3e987b1_51 -->
    <!-- Part hex_nut_grade_a___b_m2x0_4__3c416b87f78c3d5d8c04a06ae4c9fdad_22 -->
    <visual>
      <origin xyz="-0.0358 -0.0085 0.02325" rpy="-1.5708 -3.28491e-16 1.5708"/>
      <geometry>
        <mesh filename="package://arm_description/assets/hex_nut_grade_a___b_m2x0_4__3c416b87f78c3d5d8c04a06ae4c9fdad.stl"/>
      </geometry>
      <material name="hex_nut_grade_a___b_m2x0_4__3c416b87f78c3d5d8c04a06ae4c9fdad_22_material">
        <color rgba="0.603922 0.647059 0.686275 1"/>
      </material>
    </visual>
    <collision>
      <origin xyz="-0.0358 -0.0085 0.02325" rpy="-1.5708 -3.28491e-16 1.5708"/>
      <geometry>
        <mesh filename="package://arm_description/assets/hex_nut_grade_a___b_m2x0_4__3c416b87f78c3d5d8c04a06ae4c9fdad.stl"/>
      </geometry>
    </collision>
    <!-- Part ph_pan_head_screw_m2x0_40_x_6__e925606c9d0777623cf02b2ae3e987b1_52 -->
    <!-- Part ph_pan_head_screw_m2x0_40_x_6__e925606c9d0777623cf02b2ae3e987b1_53 -->
    <!-- Part ph_pan_head_screw_m2x0_40_x_6__e925606c9d0777623cf02b2ae3e987b1_54 -->
    <!-- Part ph_pan_head_screw_m2x0_40_x_6__e925606c9d0777623cf02b2ae3e987b1_55 -->
    <!-- Part hex_nut_grade_a___b_m2x0_4__3c416b87f78c3d5d8c04a06ae4c9fdad_23 -->
    <visual>
      <origin xyz="-0.0358 0.0085 0.04025" rpy="-1.5708 -3.28491e-16 1.5708"/>
      <geometry>
        <mesh filename="package://arm_description/assets/hex_nut_grade_a___b_m2x0_4__3c416b87f78c3d5d8c04a06ae4c9fdad.stl"/>
      </geometry>
      <material name="hex_nut_grade_a___b_m2x0_4__3c416b87f78c3d5d8c04a06ae4c9fdad_23_material">
        <color rgba="0.603922 0.647059 0.686275 1"/>
      </material>
    </visual>
    <collision>
      <origin xyz="-0.0358 0.0085 0.04025" rpy="-1.5708 -3.28491e-16 1.5708"/>
      <geometry>
        <mesh filename="package://arm_description/assets/hex_nut_grade_a___b_m2x0_4__3c416b87f78c3d5d8c04a06ae4c9fdad.stl"/>
      </geometry>
    </collision>
    <!-- Part ph_pan_head_screw_m2x0_40_x_6__e925606c9d0777623cf02b2ae3e987b1_56 -->
    <!-- Part hex_nut_grade_a___b_m2x0_4__3c416b87f78c3d5d8c04a06ae4c9fdad_24 -->
    <visual>
      <origin xyz="-0.0358 -0.0085 0.04025" rpy="-1.5708 -3.28491e-16 1.5708"/>
      <geometry>
        <mesh filename="package://arm_description/assets/hex_nut_grade_a___b_m2x0_4__3c416b87f78c3d5d8c04a06ae4c9fdad.stl"/>
      </geometry>
      <material name="hex_nut_grade_a___b_m2x0_4__3c416b87f78c3d5d8c04a06ae4c9fdad_24_material">
        <color rgba="0.603922 0.647059 0.686275 1"/>
      </material>
    </visual>
    <collision>
      <origin xyz="-0.0358 -0.0085 0.04025" rpy="-1.5708 -3.28491e-16 1.5708"/>
      <geometry>
        <mesh filename="package://arm_description/assets/hex_nut_grade_a___b_m2x0_4__3c416b87f78c3d5d8c04a06ae4c9fdad.stl"/>
      </geometry>
    </collision>
    <!-- Part ph_pan_head_screw_m2x0_40_x_6__e925606c9d0777623cf02b2ae3e987b1_57 -->
    <!-- Part ph_pan_head_screw_m2x0_40_x_6__e925606c9d0777623cf02b2ae3e987b1_58 -->
    <!-- Part small_support_4 -->
    <visual>
      <origin xyz="-0.033 -0.026 0.01675" rpy="1.5708 -3.28491e-16 1.5708"/>
      <geometry>
        <mesh filename="package://arm_description/assets/small_support.stl"/>
      </geometry>
      <material name="small_support_4_material">
        <color rgba="0.960784 0.960784 0.964706 1"/>
      </material>
    </visual>
    <collision>
      <origin xyz="-0.033 -0.026 0.01675" rpy="1.5708 -3.28491e-16 1.5708"/>
      <geometry>
        <mesh filename="package://arm_description/assets/small_support.stl"/>
      </geometry>
    </collision>
    <!-- Part ph_pan_head_screw_m2x0_40_x_6__e925606c9d0777623cf02b2ae3e987b1_59 -->
    <!-- Part ph_pan_head_screw_m2x0_40_x_6__e925606c9d0777623cf02b2ae3e987b1_60 -->
    <!-- Part ph_pan_head_screw_m2x0_40_x_6__e925606c9d0777623cf02b2ae3e987b1_61 -->
    <!-- Part ph_pan_head_screw_m2x0_40_x_6__e925606c9d0777623cf02b2ae3e987b1_62 -->
    <!-- Part ph_pan_head_screw_m2x0_40_x_6__e925606c9d0777623cf02b2ae3e987b1_63 -->
    <!-- Part ph_pan_head_screw_m2x0_40_x_6__e925606c9d0777623cf02b2ae3e987b1_64 -->
    <!-- Part ph_pan_head_screw_m2x0_40_x_6__e925606c9d0777623cf02b2ae3e987b1_65 -->
    <!-- Part wheel_gear_v6_5 -->
    <visual>
      <origin xyz="-1.11022e-16 0 0.0055" rpy="-1.5708 5.56097e-30 9.74002e-31"/>
      <geometry>
        <mesh filename="package://arm_description/assets/wheel_gear_v6__2.stl"/>
      </geometry>
      <material name="wheel_gear_v6_5_material">
        <color rgba="0.960784 0.960784 0.964706 1"/>
      </material>
    </visual>
    <collision>
      <origin xyz="-1.11022e-16 0 0.0055" rpy="-1.5708 5.56097e-30 9.74002e-31"/>
      <geometry>
        <mesh filename="package://arm_description/assets/wheel_gear_v6__2.stl"/>
      </geometry>
    </collision>
    <!-- Part ph_pan_head_screw_m2x0_40_x_6__e925606c9d0777623cf02b2ae3e987b1_66 -->
    <!-- Part ph_pan_head_screw_m2x0_40_x_6__e925606c9d0777623cf02b2ae3e987b1_67 -->
    <!-- Part ph_pan_head_screw_m2x0_40_x_6__e925606c9d0777623cf02b2ae3e987b1_68 -->
    <!-- Part large_support_4 -->
    <visual>
      <origin xyz="-0.033 -0.015 -0.0015" rpy="-6.31089e-30 -1.5708 0"/>
      <geometry>
        <mesh filename="package://arm_description/assets/large_support.stl"/>
      </geometry>
      <material name="large_support_4_material">
        <color rgba="0.960784 0.960784 0.964706 1"/>
      </material>
    </visual>
    <collision>
      <origin xyz="-0.033 -0.015 -0.0015" rpy="-6.31089e-30 -1.5708 0"/>
      <geometry>
        <mesh filename="package://arm_description/assets/large_support.stl"/>
      </geometry>
    </collision>
    <!-- Part din_en_iso_4762_m2_5x25_ipt_v2_21 -->
    <!-- Part din_en_iso_4762_m2_5x25_ipt_v2_22 -->
    <!-- Part din_en_iso_4762_m2_5x25_ipt_v2_23 -->
    <!-- Part din_en_iso_4762_m2_5x25_ipt_v2_24 -->
    <!-- Part servo_base_6 -->
    <visual>
      <origin xyz="-0.107 0.024 0.03175" rpy="1.5708 4.39513e-16 -1.5708"/>
      <geometry>
        <mesh filename="package://arm_description/assets/servo_base__2.stl"/>
      </geometry>
      <material name="servo_base_6_material">
        <color rgba="0.313725 0.313725 0.313725 1"/>
      </material>
    </visual>
    <collision>
      <origin xyz="-0.107 0.024 0.03175" rpy="1.5708 4.39513e-16 -1.5708"/>
      <geometry>
        <mesh filename="package://arm_description/assets/servo_base__2.stl"/>
      </geometry>
    </collision>
    <!-- Part 6mm_bearing_v2_4 -->
    <visual>
      <origin xyz="-2.22045e-16 1.55854e-18 0.0595" rpy="-1.5708 1.5708 0"/>
      <geometry>
        <mesh filename="package://arm_description/assets/6mm_bearing_v2.stl"/>
      </geometry>
      <material name="6mm_bearing_v2_4_material">
        <color rgba="0.627451 0.627451 0.627451 1"/>
      </material>
    </visual>
    <collision>
      <origin xyz="-2.22045e-16 1.55854e-18 0.0595" rpy="-1.5708 1.5708 0"/>
      <geometry>
        <mesh filename="package://arm_description/assets/6mm_bearing_v2.stl"/>
      </geometry>
    </collision>
    <!-- Part wheel_v5_4 -->
    <visual>
      <origin xyz="-1.11022e-16 5.14996e-19 0.058" rpy="1.5708 -9.46633e-30 -3.14159"/>
      <geometry>
        <mesh filename="package://arm_description/assets/wheel_v5.stl"/>
      </geometry>
      <material name="wheel_v5_4_material">
        <color rgba="0.960784 0.960784 0.964706 1"/>
      </material>
    </visual>
    <collision>
      <origin xyz="-1.11022e-16 5.14996e-19 0.058" rpy="1.5708 -9.46633e-30 -3.14159"/>
      <geometry>
        <mesh filename="package://arm_description/assets/wheel_v5.stl"/>
      </geometry>
    </collision>
  </link>
  <!-- Link link_6 -->
  <link name="link_6">
    <inertial>
      <origin xyz="0 0 0" rpy="0 0 0"/>
      <mass value="1e-09"/>
      <inertia ixx="1e-09" ixy="0" ixz="0" iyy="1e-09" iyz="0" izz="1e-09"/>
    </inertial>
    <!-- Part wheel_gear_v6_6 -->
    <visual>
      <origin xyz="5.42101e-20 0 0.0055" rpy="-1.5708 -4.48041e-19 0"/>
      <geometry>
        <mesh filename="package://arm_description/assets/wheel_gear_v6__2.stl"/>
      </geometry>
      <material name="wheel_gear_v6_6_material">
        <color rgba="0.960784 0.960784 0.964706 1"/>
      </material>
    </visual>
    <collision>
      <origin xyz="5.42101e-20 0 0.0055" rpy="-1.5708 -4.48041e-19 0"/>
      <geometry>
        <mesh filename="package://arm_description/assets/wheel_gear_v6__2.stl"/>
      </geometry>
    </collision>
  </link>
  <!-- Frame tcp (dummy link + fixed joint) -->
  <link name="tcp">
    <origin xyz="0 0 0" rpy="0 -0 0"/>
    <inertial>
      <origin xyz="0 0 0" rpy="0 0 0"/>
      <mass value="1e-9"/>
      <inertia ixx="0" ixy="0" ixz="0" iyy="0" iyz="0" izz="0"/>
    </inertial>
  </link>
  <joint name="tcp_frame" type="fixed">
    <origin xyz="1.0842e-19 0 0.0005" rpy="3.14159 -4.48041e-19 0"/>
    <parent link="link_6"/>
    <child link="tcp"/>
    <axis xyz="0 0 0"/>
  </joint>
  <!-- Joint from link_5 to link_6 -->
  <joint name="joint_6" type="revolute">
    <origin xyz="-0.095 0.0315 0.03175" rpy="1.5708 1.5708 0"/>
    <parent link="link_5"/>
    <child link="link_6"/>
    <axis xyz="0 0 1"/>
    <limit effort="10" velocity="1" lower="0" upper="4.71239"/>
  </joint>
  <!-- Joint from link_4 to link_5 -->
  <joint name="joint_5" type="revolute">
    <origin xyz="-0.095 0.0315 0.03175" rpy="1.5708 -5.58182e-14 1.16592e-14"/>
    <parent link="link_4"/>
    <child link="link_5"/>
    <axis xyz="0 0 1"/>
    <limit effort="10" velocity="1" lower="0" upper="3.14159"/>
  </joint>
  <!-- Joint from link_3 to link_4 -->
  <joint name="joint_4" type="revolute">
    <origin xyz="-1.83989e-15 0.224 -4.16334e-16" rpy="-3.14159 -8.69067e-16 -1.5708"/>
    <parent link="link_3"/>
    <child link="link_4"/>
    <axis xyz="0 0 1"/>
    <limit effort="10" velocity="1" lower="-1.5708" upper="1.5708"/>
  </joint>
  <!-- Joint from link_2 to link_3 -->
  <joint name="joint_3" type="revolute">
    <origin xyz="-0.166 -1.91133e-18 -2.08167e-16" rpy="3.14159 -8.28144e-16 -1.5708"/>
    <parent link="link_2"/>
    <child link="link_3"/>
    <axis xyz="0 0 1"/>
    <limit effort="10" velocity="1" lower="-1.5708" upper="1.5708"/>
  </joint>
  <!-- Joint from link_1 to link_2 -->
  <joint name="joint_2" type="revolute">
    <origin xyz="-2.24205e-17 0.0315746 -0.0675" rpy="1.5708 -1.5708 0"/>
    <parent link="link_1"/>
    <child link="link_2"/>
    <axis xyz="0 0 1"/>
    <limit effort="10" velocity="1" lower="-1.5708" upper="1.5708"/>
  </joint>
  <!-- Joint from base_link to link_1 -->
  <joint name="joint_1" type="revolute">
    <origin xyz="1.54081e-17 9.14136e-05 0.0755" rpy="-3.14159 -3.6506e-16 -3.10006"/>
    <parent link="base_link"/>
    <child link="link_1"/>
    <axis xyz="0 0 1"/>
    <limit effort="10" velocity="1" lower="-3.10006" upper="1.61232"/>
  </joint>
</robot>
